data/sample_orders.csv
type,id,side,price,qty,ts
LIMIT,1,BUY,100000,100,1
LIMIT,2,SELL,101000,50,2
LIMIT,3,BUY,101000,30,3
LIMIT,4,SELL,100500,20,4
CANCEL,1,BUY,0,0,5
MARKET,5,SELL,0,10,6
LIMIT,6,BUY,100200,40,7
LIMIT,7,SELL,100200,25,8
